Exception on /register [POST]
Traceback (most recent call last):
  File "/home/patrickalkhouri/.local/lib/python3.8/site-packages/flask/app.py", line 2447, in wsgi_app
    response = self.full_dispatch_request()
  File "/home/patrickalkhouri/.local/lib/python3.8/site-packages/flask/app.py", line 1952, in full_dispatch_request
    rv = self.handle_user_exception(e)
  File "/home/patrickalkhouri/.local/lib/python3.8/site-packages/flask/app.py", line 1821, in handle_user_exception
    reraise(exc_type, exc_value, tb)
  File "/home/patrickalkhouri/.local/lib/python3.8/site-packages/flask/_compat.py", line 39, in reraise
    raise value
  File "/home/patrickalkhouri/.local/lib/python3.8/site-packages/flask/app.py", line 1950, in full_dispatch_request
    rv = self.dispatch_request()
  File "/home/patrickalkhouri/.local/lib/python3.8/site-packages/flask/app.py", line 1936, in dispatch_request
    return self.view_functions[rule.endpoint](**req.view_args)
  File "/home/patrickalkhouri/code/PatrickalKhouri/flask-application/app.py", line 41, in register
    if form.validate_on_submit():
  File "/home/patrickalkhouri/.local/lib/python3.8/site-packages/flask_wtf/form.py", line 100, in validate_on_submit
    return self.is_submitted() and self.validate()
  File "/home/patrickalkhouri/.local/lib/python3.8/site-packages/wtforms/form.py", line 318, in validate
    return super(Form, self).validate(extra)
  File "/home/patrickalkhouri/.local/lib/python3.8/site-packages/wtforms/form.py", line 150, in validate
    if not field.validate(self, extra):
  File "/home/patrickalkhouri/.local/lib/python3.8/site-packages/wtforms/fields/core.py", line 226, in validate
    stop_validation = self._run_validation_chain(form, chain)
  File "/home/patrickalkhouri/.local/lib/python3.8/site-packages/wtforms/fields/core.py", line 246, in _run_validation_chain
    validator(form, self)
  File "/home/patrickalkhouri/code/PatrickalKhouri/flask-application/forms.py", line 26, in validate_username
    user = users_collection.find({"username": username}).count()
  File "/home/patrickalkhouri/.local/lib/python3.8/site-packages/pymongo/cursor.py", line 822, in count
    return self.__collection._count(
  File "/home/patrickalkhouri/.local/lib/python3.8/site-packages/pymongo/collection.py", line 1664, in _count
    return self.__database.client._retryable_read(
  File "/home/patrickalkhouri/.local/lib/python3.8/site-packages/pymongo/mongo_client.py", line 1471, in _retryable_read
    return func(session, server, sock_info, slave_ok)
  File "/home/patrickalkhouri/.local/lib/python3.8/site-packages/pymongo/collection.py", line 1651, in _cmd
    res = self._command(
  File "/home/patrickalkhouri/.local/lib/python3.8/site-packages/pymongo/collection.py", line 238, in _command
    return sock_info.command(
  File "/home/patrickalkhouri/.local/lib/python3.8/site-packages/pymongo/pool.py", line 699, in command
    self._raise_connection_failure(error)
  File "/home/patrickalkhouri/.local/lib/python3.8/site-packages/pymongo/pool.py", line 683, in command
    return command(self, dbname, spec, slave_ok,
  File "/home/patrickalkhouri/.local/lib/python3.8/site-packages/pymongo/network.py", line 120, in command
    request_id, msg, size, max_doc_size = message._op_msg(
  File "/home/patrickalkhouri/.local/lib/python3.8/site-packages/pymongo/message.py", line 714, in _op_msg
    return _op_msg_uncompressed(
bson.errors.InvalidDocument: cannot encode object: <wtforms.fields.core.StringField object at 0x7f6929a8ffa0>, of type: <class 'wtforms.fields.core.StringField'>
